[2024-09-27T15:31:38.542+0000] {local_task_job_runner.py:123} INFO - ::group::Pre task execution logs
[2024-09-27T15:31:38.555+0000] {taskinstance.py:2612} INFO - Dependencies all met for dep_context=non-requeueable deps ti=<TaskInstance: etl_costos_ventas.load_data manual__2024-09-27T15:31:32.736195+00:00 [queued]>
[2024-09-27T15:31:38.562+0000] {taskinstance.py:2612} INFO - Dependencies all met for dep_context=requeueable deps ti=<TaskInstance: etl_costos_ventas.load_data manual__2024-09-27T15:31:32.736195+00:00 [queued]>
[2024-09-27T15:31:38.562+0000] {taskinstance.py:2865} INFO - Starting attempt 1 of 1
[2024-09-27T15:31:38.572+0000] {taskinstance.py:2888} INFO - Executing <Task(PythonOperator): load_data> on 2024-09-27 15:31:32.736195+00:00
[2024-09-27T15:31:38.579+0000] {warnings.py:112} WARNING - /home/***/.local/lib/python3.12/site-packages/***/task/task_runner/standard_task_runner.py:70: DeprecationWarning: This process (pid=94) is multi-threaded, use of fork() may lead to deadlocks in the child.
  pid = os.fork()

[2024-09-27T15:31:38.580+0000] {standard_task_runner.py:72} INFO - Started process 96 to run task
[2024-09-27T15:31:38.580+0000] {standard_task_runner.py:104} INFO - Running: ['***', 'tasks', 'run', 'etl_costos_ventas', 'load_data', 'manual__2024-09-27T15:31:32.736195+00:00', '--job-id', '37', '--raw', '--subdir', 'DAGS_FOLDER/RPA_dag.py', '--cfg-path', '/tmp/tmpk6yzpg3i']
[2024-09-27T15:31:38.581+0000] {standard_task_runner.py:105} INFO - Job 37: Subtask load_data
[2024-09-27T15:31:38.617+0000] {task_command.py:467} INFO - Running <TaskInstance: etl_costos_ventas.load_data manual__2024-09-27T15:31:32.736195+00:00 [running]> on host 32d53c0d21c3
[2024-09-27T15:31:38.684+0000] {taskinstance.py:3131} INFO - Exporting env vars: AIRFLOW_CTX_DAG_OWNER='***' AIRFLOW_CTX_DAG_ID='etl_costos_ventas' AIRFLOW_CTX_TASK_ID='load_data' AIRFLOW_CTX_EXECUTION_DATE='2024-09-27T15:31:32.736195+00:00' AIRFLOW_CTX_TRY_NUMBER='1' AIRFLOW_CTX_DAG_RUN_ID='manual__2024-09-27T15:31:32.736195+00:00'
[2024-09-27T15:31:38.686+0000] {logging_mixin.py:190} INFO - Task instance is in running state
[2024-09-27T15:31:38.686+0000] {logging_mixin.py:190} INFO -  Previous state of the Task instance: queued
[2024-09-27T15:31:38.686+0000] {logging_mixin.py:190} INFO - Current task name:load_data state:running start_date:2024-09-27 15:31:38.556234+00:00
[2024-09-27T15:31:38.687+0000] {logging_mixin.py:190} INFO - Dag name:etl_costos_ventas and current dag run status:running
[2024-09-27T15:31:38.687+0000] {taskinstance.py:731} INFO - ::endgroup::
[2024-09-27T15:31:38.742+0000] {taskinstance.py:3310} ERROR - Task failed with exception
Traceback (most recent call last):
  File "/home/airflow/.local/lib/python3.12/site-packages/airflow/models/taskinstance.py", line 767, in _execute_task
    result = _execute_callable(context=context, **execute_callable_kwargs)
             ^^^^^^^^^^^^^^^^^^^^^^^^^^^^^^^^^^^^^^^^^^^^^^^^^^^^^^^^^^^^^
  File "/home/airflow/.local/lib/python3.12/site-packages/airflow/models/taskinstance.py", line 733, in _execute_callable
    return ExecutionCallableRunner(
           ^^^^^^^^^^^^^^^^^^^^^^^^
  File "/home/airflow/.local/lib/python3.12/site-packages/airflow/utils/operator_helpers.py", line 252, in run
    return self.func(*args, **kwargs)
           ^^^^^^^^^^^^^^^^^^^^^^^^^^
  File "/home/airflow/.local/lib/python3.12/site-packages/airflow/models/baseoperator.py", line 406, in wrapper
    return func(self, *args, **kwargs)
           ^^^^^^^^^^^^^^^^^^^^^^^^^^^
  File "/home/airflow/.local/lib/python3.12/site-packages/airflow/operators/python.py", line 238, in execute
    return_value = self.execute_callable()
                   ^^^^^^^^^^^^^^^^^^^^^^^
  File "/home/airflow/.local/lib/python3.12/site-packages/airflow/operators/python.py", line 256, in execute_callable
    return runner.run(*self.op_args, **self.op_kwargs)
           ^^^^^^^^^^^^^^^^^^^^^^^^^^^^^^^^^^^^^^^^^^^
  File "/home/airflow/.local/lib/python3.12/site-packages/airflow/utils/operator_helpers.py", line 252, in run
    return self.func(*args, **kwargs)
           ^^^^^^^^^^^^^^^^^^^^^^^^^^
  File "/opt/airflow/dags/RPA_dag.py", line 106, in load_data
    with pd.ExcelWriter('/opt/airflow/data_fuente/Datos_Modelo_Corregido.xlsx') as writer:
         ^^^^^^^^^^^^^^^^^^^^^^^^^^^^^^^^^^^^^^^^^^^^^^^^^^^^^^^^^^^^^^^^^^^^^^
  File "/home/airflow/.local/lib/python3.12/site-packages/pandas/io/excel/_xlsxwriter.py", line 205, in __init__
    super().__init__(
  File "/home/airflow/.local/lib/python3.12/site-packages/pandas/io/excel/_base.py", line 1263, in __init__
    self._handles = get_handle(
                    ^^^^^^^^^^^
  File "/home/airflow/.local/lib/python3.12/site-packages/pandas/io/common.py", line 872, in get_handle
    handle = open(handle, ioargs.mode)
             ^^^^^^^^^^^^^^^^^^^^^^^^^
PermissionError: [Errno 13] Permission denied: '/opt/airflow/data_fuente/Datos_Modelo_Corregido.xlsx'
[2024-09-27T15:31:38.757+0000] {logging_mixin.py:190} INFO - Task instance in failure state
[2024-09-27T15:31:38.757+0000] {logging_mixin.py:190} INFO - Task start:2024-09-27 15:31:38.556234+00:00 end:2024-09-27 15:31:38.756588+00:00 duration:0.200354
[2024-09-27T15:31:38.758+0000] {logging_mixin.py:190} INFO - Task:<Task(PythonOperator): load_data> dag:<DAG: etl_costos_ventas> dagrun:<DagRun etl_costos_ventas @ 2024-09-27 15:31:32.736195+00:00: manual__2024-09-27T15:31:32.736195+00:00, state:running, queued_at: 2024-09-27 15:31:32.749059+00:00. externally triggered: True>
[2024-09-27T15:31:38.758+0000] {logging_mixin.py:190} INFO - Failure caused by [Errno 13] Permission denied: '/opt/***/data_fuente/Datos_Modelo_Corregido.xlsx'
[2024-09-27T15:31:38.758+0000] {taskinstance.py:1225} INFO - Marking task as FAILED. dag_id=etl_costos_ventas, task_id=load_data, run_id=manual__2024-09-27T15:31:32.736195+00:00, execution_date=20240927T153132, start_date=20240927T153138, end_date=20240927T153138
[2024-09-27T15:31:38.769+0000] {taskinstance.py:340} INFO - ::group::Post task execution logs
[2024-09-27T15:31:38.769+0000] {standard_task_runner.py:124} ERROR - Failed to execute job 37 for task load_data ([Errno 13] Permission denied: '/opt/airflow/data_fuente/Datos_Modelo_Corregido.xlsx'; 96)
Traceback (most recent call last):
  File "/home/airflow/.local/lib/python3.12/site-packages/airflow/task/task_runner/standard_task_runner.py", line 117, in _start_by_fork
    ret = args.func(args, dag=self.dag)
          ^^^^^^^^^^^^^^^^^^^^^^^^^^^^^
  File "/home/airflow/.local/lib/python3.12/site-packages/airflow/cli/cli_config.py", line 49, in command
    return func(*args, **kwargs)
           ^^^^^^^^^^^^^^^^^^^^^
  File "/home/airflow/.local/lib/python3.12/site-packages/airflow/utils/cli.py", line 115, in wrapper
    return f(*args, **kwargs)
           ^^^^^^^^^^^^^^^^^^
  File "/home/airflow/.local/lib/python3.12/site-packages/airflow/cli/commands/task_command.py", line 483, in task_run
    task_return_code = _run_task_by_selected_method(args, _dag, ti)
                       ^^^^^^^^^^^^^^^^^^^^^^^^^^^^^^^^^^^^^^^^^^^^
  File "/home/airflow/.local/lib/python3.12/site-packages/airflow/cli/commands/task_command.py", line 256, in _run_task_by_selected_method
    return _run_raw_task(args, ti)
           ^^^^^^^^^^^^^^^^^^^^^^^
  File "/home/airflow/.local/lib/python3.12/site-packages/airflow/cli/commands/task_command.py", line 341, in _run_raw_task
    return ti._run_raw_task(
           ^^^^^^^^^^^^^^^^^
  File "/home/airflow/.local/lib/python3.12/site-packages/airflow/utils/session.py", line 97, in wrapper
    return func(*args, session=session, **kwargs)
           ^^^^^^^^^^^^^^^^^^^^^^^^^^^^^^^^^^^^^^
  File "/home/airflow/.local/lib/python3.12/site-packages/airflow/models/taskinstance.py", line 3004, in _run_raw_task
    return _run_raw_task(
           ^^^^^^^^^^^^^^
  File "/home/airflow/.local/lib/python3.12/site-packages/airflow/models/taskinstance.py", line 273, in _run_raw_task
    TaskInstance._execute_task_with_callbacks(
  File "/home/airflow/.local/lib/python3.12/site-packages/airflow/models/taskinstance.py", line 3158, in _execute_task_with_callbacks
    result = self._execute_task(context, task_orig)
             ^^^^^^^^^^^^^^^^^^^^^^^^^^^^^^^^^^^^^^
  File "/home/airflow/.local/lib/python3.12/site-packages/airflow/models/taskinstance.py", line 3182, in _execute_task
    return _execute_task(self, context, task_orig)
           ^^^^^^^^^^^^^^^^^^^^^^^^^^^^^^^^^^^^^^^
  File "/home/airflow/.local/lib/python3.12/site-packages/airflow/models/taskinstance.py", line 767, in _execute_task
    result = _execute_callable(context=context, **execute_callable_kwargs)
             ^^^^^^^^^^^^^^^^^^^^^^^^^^^^^^^^^^^^^^^^^^^^^^^^^^^^^^^^^^^^^
  File "/home/airflow/.local/lib/python3.12/site-packages/airflow/models/taskinstance.py", line 733, in _execute_callable
    return ExecutionCallableRunner(
           ^^^^^^^^^^^^^^^^^^^^^^^^
  File "/home/airflow/.local/lib/python3.12/site-packages/airflow/utils/operator_helpers.py", line 252, in run
    return self.func(*args, **kwargs)
           ^^^^^^^^^^^^^^^^^^^^^^^^^^
  File "/home/airflow/.local/lib/python3.12/site-packages/airflow/models/baseoperator.py", line 406, in wrapper
    return func(self, *args, **kwargs)
           ^^^^^^^^^^^^^^^^^^^^^^^^^^^
  File "/home/airflow/.local/lib/python3.12/site-packages/airflow/operators/python.py", line 238, in execute
    return_value = self.execute_callable()
                   ^^^^^^^^^^^^^^^^^^^^^^^
  File "/home/airflow/.local/lib/python3.12/site-packages/airflow/operators/python.py", line 256, in execute_callable
    return runner.run(*self.op_args, **self.op_kwargs)
           ^^^^^^^^^^^^^^^^^^^^^^^^^^^^^^^^^^^^^^^^^^^
  File "/home/airflow/.local/lib/python3.12/site-packages/airflow/utils/operator_helpers.py", line 252, in run
    return self.func(*args, **kwargs)
           ^^^^^^^^^^^^^^^^^^^^^^^^^^
  File "/opt/airflow/dags/RPA_dag.py", line 106, in load_data
    with pd.ExcelWriter('/opt/airflow/data_fuente/Datos_Modelo_Corregido.xlsx') as writer:
         ^^^^^^^^^^^^^^^^^^^^^^^^^^^^^^^^^^^^^^^^^^^^^^^^^^^^^^^^^^^^^^^^^^^^^^
  File "/home/airflow/.local/lib/python3.12/site-packages/pandas/io/excel/_xlsxwriter.py", line 205, in __init__
    super().__init__(
  File "/home/airflow/.local/lib/python3.12/site-packages/pandas/io/excel/_base.py", line 1263, in __init__
    self._handles = get_handle(
                    ^^^^^^^^^^^
  File "/home/airflow/.local/lib/python3.12/site-packages/pandas/io/common.py", line 872, in get_handle
    handle = open(handle, ioargs.mode)
             ^^^^^^^^^^^^^^^^^^^^^^^^^
PermissionError: [Errno 13] Permission denied: '/opt/airflow/data_fuente/Datos_Modelo_Corregido.xlsx'
[2024-09-27T15:31:38.794+0000] {local_task_job_runner.py:266} INFO - Task exited with return code 1
[2024-09-27T15:31:38.809+0000] {taskinstance.py:3900} INFO - 0 downstream tasks scheduled from follow-on schedule check
[2024-09-27T15:31:38.810+0000] {local_task_job_runner.py:245} INFO - ::endgroup::
